# 天翼云盘签到记录

[![签到状态](https://github.com/211847750/189pan/actions/workflows/main.yml/badge.svg)](https://github.com/211847750/189pan/actions/workflows/main.yml) [![项目主页](https://img.shields.io/badge/GitHub-项目主页-blue?logo=github)](https://github.com/211847750/189pan)

**最后更新:** 2025-10-02 21:42:55 CST

## 快速导航

- 🔄 [查看Action运行记录](https://github.com/211847750/189pan/actions)
- 📋 [查看最新运行](https://github.com/211847750/189pan/actions/runs/18194842164)
- 🏠 [返回项目主页](https://github.com/211847750/189pan)
- ⚙️ [手动触发签到](https://github.com/211847750/189pan/actions/workflows/main.yml)

## 签到详情

# 天翼云盘自动签到抽奖程序

## 执行概览
- **启动时间**: 2025-10-02 21:42:55
- **账户数量**: 2 个

## 账户1
登录过程出错: HTTPSConnectionPool(host='open.e.189.cn', port=443): Max retries exceeded with url: /api/logbox/oauth2/autoLogin.do?appId=cloud&version=v1.1&clientType=20010&format=redirect&paras=A0A0EA51EE93192DD92BB6E417833A29C144F916FB26924B059E321DA1D40AD6A55106E1BC830ABB366997C6B9530160E157F6D17C585E95B0EF793CE3AC29EDEB6C3287DA468E72B6C0337CF6529F9DFC3A0A9D82D3AB77595860F3B368FCB5BF351B3B85BA0DC7EA1BF8A02A6CFE0A64F42BBC4521AF7702F64D26CF34B66FA9E67AF8F795965B88AF3974EEDC851AA2D89C1D4EC59A320D9400342A1C556A916DAC2E083223C493C18CFA0EEF1ACC044A33FAEFBBB457D54F242BC53787034CA6C96C781DBA69A4830709336003872CEC9873A3D179F5D3E736B5CDE564DB47FF97229A145438741528EEF6802329DB2E6CCBA87A830A2FE940CAAF769468FF10FFED06B87D69078AC643F933F26EEF19EF44CFBA6378F3F4330B0C813E3238CDC51DF4D51A9D8F2BEC916E0EEEFA1A07FBA32A8218085BCDCB37A48AF808415719173007A34EF7EFAF3358E10B09F89D8DBF9295316F50437D232552A1E2A9328C25BCEAD8455FDF2D4885FF30B88565DA623F88358CA53FF946406A20299283924DF699C42E70F0A352AA6BD26A1532BDC2D1145FE322D9AE8EEA1224CC34A3D405DADCAF1F69FB03EEA94F005DDF8820C009EA7FEB224C90F371C02F869D33DAA471E44BC8F34A07B29BDCCFFC52EB3F4A2CA73CF3BC16820AD9CFEC453B072A33E4CFBD5FEB2E96EFFDD35F94C31BFFCBFB91E0A977DF6F8850948BDE44D611832F01263904D8ECF5184E72CC606F14410C78EEEF&sign=BCC357C7DA86A54EDE0A6596418C63C7E687B16A (Caused by NewConnectionError('<urllib3.connection.HTTPSConnection object at 0x7fba725e4a50>: Failed to establish a new connection: [Errno 101] Network is unreachable'))
### 执行结果
- **登录状态**: 登录失败
- **签到结果**: 

## 账户2
登录过程出错: HTTPSConnectionPool(host='open.e.189.cn', port=443): Max retries exceeded with url: /api/logbox/oauth2/autoLogin.do?appId=cloud&version=v1.1&clientType=20010&format=redirect&paras=1C615BC5021EC737214C59939AD2FDD57BBA07F64D5B6C5A1B0F32C036F3B067C08E6C02506F5ECCFB061F918D53A60844C49CC1CD64AAD86F78FA71AAF71F8B20BD4DA56DDBD56032996B3A0426FE986C7F40D228CD9AAD076E202D4E56F0BB6171AFDEF09F8BC6AC89A2F7E50D62CD98EE91D80986A55B2D1BD703BFD4C5D0DB565058605D553504D8CAF2861514E5EF454F945E1A035C558EB9AB0FBA6A1FDDA9C256D4BB2DF314A87A8179BB9F319F6A5E94DD5726F830060DD66B9EE240C6E3497F5B54F5BB7573706E863C689EA1A95F7E1CCDDB56AD912D3F971172167E7E260A6048849D900F5682F5BAEF0D3F0990A98A5C727403AA3D82253D92AEBA5914617060FA6CDF5DAA3C34E04F05DF9A848093DC86CD88EE8E937C8E02598891F9AE02762D0EF1575681FE4FE6148FF154E0FD119809DDAAE46455FA238582B91D1F5BF077F197DE674B939DE6C0ADE541E42D293B003D367BA654B9757E21F1CB7F97C13863ECB64CFB4DA178C460C52B0B75D04B629175E8F68BB90A67036DFBC1868BFFC72586C9FD2A2D3D17AC39674F9C437ECD06B1630EF0C641FA1918109FB8AF0EC0170787EF2A5D72040BA59FE9A9B9C5173E9829B51A8FD1214E0F823E9A5004CE7F0E87E04E987ED8D727C086198333BAAAF81BD480370BFBE93E392C18EAB0FA9D5174618109BC3E4AD4D206CCCD71761977C1B88C1AE13C3F9F0942A9F77563F6F581BA7B34FF944C104C5424BE2BFA&sign=D4D32A1AAD0A38E0D08D620BF072025BB693D37B (Caused by NewConnectionError('<urllib3.connection.HTTPSConnection object at 0x7fba725ec290>: Failed to establish a new connection: [Errno 101] Network is unreachable'))
### 执行结果
- **登录状态**: 登录失败
- **签到结果**: 

---
## 执行统计
- **结束时间**: 2025-10-02 21:51:58
- **运行时长**: 542.25 秒

✅ **所有账户处理完成！**
