# 天翼云盘签到记录

[![签到状态](https://github.com/211847750/189pan/actions/workflows/main.yml/badge.svg)](https://github.com/211847750/189pan/actions/workflows/main.yml) [![项目主页](https://img.shields.io/badge/GitHub-项目主页-blue?logo=github)](https://github.com/211847750/189pan)

**最后更新:** 2025-09-17 10:41:59 CST

## 快速导航

- 🔄 [查看Action运行记录](https://github.com/211847750/189pan/actions)
- 📋 [查看最新运行](https://github.com/211847750/189pan/actions/runs/17785011555)
- 🏠 [返回项目主页](https://github.com/211847750/189pan)
- ⚙️ [手动触发签到](https://github.com/211847750/189pan/actions/workflows/main.yml)

## 签到详情

# 天翼云盘自动签到抽奖程序

## 执行概览
- **启动时间**: 2025-09-17 10:42:00
- **账户数量**: 2 个

## 账户1
登录过程出错: HTTPSConnectionPool(host='open.e.189.cn', port=443): Max retries exceeded with url: /api/logbox/oauth2/autoLogin.do?appId=cloud&version=v1.1&clientType=20010&format=redirect&paras=6DD95CFC7528893D2F370C75F67A2D14DCFD33A3EE0734E1EEA41DA6981F788231B4E161D09EE5F7805537309C463EA92CD9826D89AD9E139B21946CCCBF33BAC411DA945377563108177244B0CEC33A3546C97917B40C14298F546604ADE90B0DE72D7188D26D99A2BE8B28C8D95E55A4F9DF90A215BFB04C142BA6F0CA60489F59A35D4F69629969722DD0D269B4C31DEAF375D3FD8030B2BC0AABF7A729EF9408B9B660805BB03A102945A44A3ECA45C067A76C944A9B11B552D9DE31A62823A26A6D7379D115097835BC91CCAC49EEB13CEB62F890E38D6D0BF21D46A81D7683A3800CD8135DC655C456443DDAD2A21C7F41837653C9B10E5C48382556117D9C082D7DABF70842CB621C2BD4B4EB56113CC0A3EE37865CEEE4A644E5550E8530EB6E65F0BCF17375CA7FE6DBC67F4A185D86188EB192E399734FF4D032E48302366D7BFEB78B1C7E5EF6A5DFCE15C46E01A0774D4A3B0961832AC48037E5534AE7C1F49CF4D6CA1FBBFCB89E2CBD296C8FD251A6EA74FA7D24C627593DE8203EC9DE5E5EB34AB280740CD606F88C194D39EB679C6B96DD8BFDFCF5B0CB3A6647977E003BEF1211468748CEDF8D1593906EB6C9768B8D6C15D575184E53828893B2CF1A2F67DC76B3691082395BCC171E5F8E8ECDDB87BCD403A1B89FE931BFC8C9C36A2D74B096D0B83A0BD5268DD638997C220F82A41B232215461D7A8BD5E5BD76FA6EC8650AA91C8650C0A47185F8F2D7737EED96&sign=AC4CC9A12C80AFECDB386197093E8565362759D8 (Caused by NewConnectionError('<urllib3.connection.HTTPSConnection object at 0x7f2ef9ac4bd0>: Failed to establish a new connection: [Errno 101] Network is unreachable'))
### 执行结果
- **登录状态**: 登录失败
- **签到结果**: 

## 账户2
登录过程出错: HTTPSConnectionPool(host='open.e.189.cn', port=443): Max retries exceeded with url: /api/logbox/oauth2/autoLogin.do?appId=cloud&version=v1.1&clientType=20010&format=redirect&paras=2907C2AB7F86F302F54D8601AEDAED70BC4BF5AB21121AE87AC10840FDD1F0A6B7B6BDC8DFEE518E82CA6A9838124BB832D69E52F1BC68A919B8123892D5CF6690DAE65FAF24C2B51DE626419E5CD883F0922A00531FCBF5343C4A2220794D980F948101E1050141D0814FB4037AFF93869C9240B82BC6E8D81DF24E891E72FC409D481CF6104BCDA99E0F23128DDBD3E992EF0957E2EA2737CE8212E986F0BA4586F23B86FE72E1B8CB038A8A07E62C72B5C767AD0EC26ED9BD2F2E34B41ED5BA76F7C081F8D95FC21A3AEE1D33843FCE78927011B727DE0C6D5ED7E2ECA541A570CA02D8279D1B2FF4BD48221C42AB60404A4BE0A35E1929445D82BB5435C35E719C15B87FEDC06A7DC48339285F6981BC7FF910E9B86A6CC047298A8658D11FD81F71F513F47EFDE39406565B08589D6B26D986F261C82EA4A23497470705FA08774618C4DD5A4FC52F162B4121C9966092588CBCE9962D6235B7167D8015C58FA5CC4A332E311B413469CC5A3F5627D3C5A586EA6775711F1A3B7750823AFADDE55C510F755FA6AED42EB45A4DE155C1E10555CC5D1C07A296EAC736E116ADF7B3A468D150E9BACE3DC213001D4914A60F9B42920A07B85F8553D58D6247EF3B1FF802B72756185D2043888A8D780DD21D86BA03948D1A01B4540340F5BCC7D58DAE777D8DF574C2DEF2A3B5434048ACCFA26220C26BE3A986BAE44432D964FB5D4A50C8A832E762FC1B7DADA62F6D09E558BA128020&sign=5579F9C6070552F3B1E96F9022DA855A2ADFB84B (Caused by NewConnectionError('<urllib3.connection.HTTPSConnection object at 0x7f2ef9acc410>: Failed to establish a new connection: [Errno 101] Network is unreachable'))
### 执行结果
- **登录状态**: 登录失败
- **签到结果**: 

---
## 执行统计
- **结束时间**: 2025-09-17 10:51:01
- **运行时长**: 541.37 秒

✅ **所有账户处理完成！**
