# 天翼云盘签到记录

[![签到状态](https://github.com/211847750/189pan/actions/workflows/main.yml/badge.svg)](https://github.com/211847750/189pan/actions/workflows/main.yml) [![项目主页](https://img.shields.io/badge/GitHub-项目主页-blue?logo=github)](https://github.com/211847750/189pan)

**最后更新:** 2025-09-24 10:45:46 CST

## 快速导航

- 🔄 [查看Action运行记录](https://github.com/211847750/189pan/actions)
- 📋 [查看最新运行](https://github.com/211847750/189pan/actions/runs/17964756955)
- 🏠 [返回项目主页](https://github.com/211847750/189pan)
- ⚙️ [手动触发签到](https://github.com/211847750/189pan/actions/workflows/main.yml)

## 签到详情

# 天翼云盘自动签到抽奖程序

## 执行概览
- **启动时间**: 2025-09-24 10:45:47
- **账户数量**: 2 个

## 账户1
登录过程出错: HTTPSConnectionPool(host='open.e.189.cn', port=443): Max retries exceeded with url: /api/logbox/oauth2/autoLogin.do?appId=cloud&version=v1.1&clientType=20010&format=redirect&paras=F5D59E703C3E4AF9BC9C3187D2C431917B1F63A4FB05F879B4D7FF3DC8C4DF2F630E7A56E55BCD3221EEB8A0D10F5B7FCA2393D13DFACFFFEE0892E814D1358634AE625ABD90E095F0D93C6720DB905600DA1E0FA2DE1B6C2B1744327E7033C6B0635678C8F30562A7A935DDD45AE10E938FAA639188F808A563C1B5CFAF149827FB0F13BB3910A223F2BAA243651D9B9A397B4D6AACD2A7B5C7F2C774A9A92160A18B4D5E875891177872E34B9EA990B79D978988A85D6987BF841E6836358287D75814A9B2BD87726E2C1718FE3C55293E3770EBE370246E631EF7AD2F3277BF236D9BC5D152EC5F954DDA3554F48D3162F22FFF75E8EAEDC28948B3F5F8B4DB05C71C16F24FDB26DEB421BDC2ADACE16D66811F0630EE1AF79FE5766609DC955FDF9EFC92E18B582149D998697EB2C2BC688400605DA502F56AEF3E4FADBFA487F753B8A6B547F65D74316B5A122A34A8B8C0EA908B753AF4B18C06C1F9F9346B0790362B77301D6A2926A9B681655FEF12E4ECFA8794E149EC580ADED7DA7B19B3958EA8A97646E0052903754B9D93AEB7581502167664F1D851586782EF6DB9A70D033B6CC3303ABB40C29C8623EB5A25C36430A68150CDA27FBC616E687B0A723312298960D3B4A26BB9D47B3C108FD9B44F91D5AA0ECEDA8B12738F506DC7797D96CA257D89735A1F0402C42D8870CDB1DF20474542DF086B8DFD70CFD745A9F7D2CA82C59ABC68081CC1ADBE36CCB44D75DDD986&sign=73675AAEF815320ED74C50D246BDA7FF9F1694BA (Caused by NewConnectionError('<urllib3.connection.HTTPSConnection object at 0x7f3b8b6c4bd0>: Failed to establish a new connection: [Errno 101] Network is unreachable'))
### 执行结果
- **登录状态**: 登录失败
- **签到结果**: 

## 账户2
登录过程出错: HTTPSConnectionPool(host='open.e.189.cn', port=443): Max retries exceeded with url: /api/logbox/oauth2/autoLogin.do?appId=cloud&version=v1.1&clientType=20010&format=redirect&paras=D50CD4F3783E3C7F851B2C7A5C7EE39FA12FBBCC66972E2B62B207025424897F1E44C60C962076DF6D1F4B2612A1C2320A6480E1BF306D210789723CBC80562211EC038F1DA53C4F84BE73A6E28582BF9A4B1371F3033ADDCF47F3B3BAF29F5845215875BD13822BD50C28C7A870768985DD605240C7BF96E2792A8519D21FC73C425AEC2AF40AE41DDB7F0B04A06C80C1DA4488B783BCC72F8A0C92A3920494C09227B287F254841AC4AD9177FF99F125A19050902C8AF092863E48A964003EA2460E4B5A5AA6615EA1F08D637AC80F4145B39318852D420939EDC0FC5D62D1F2B46DE8219DC952E5FCC03E17947729E898F068C16AE3D04BC511A091E626EAC395653F2D81EA7DCDA1B3751F940DFA22563D15A7E951B0C096356D88CA344F619F0D973A8765E3FBD0653C0C441EDF14F2C981540D7180C9EE1D51BF918D3A51852C48BCE588DE0179991A71536FFFB19520D0B3172934D71ADD5025F4D0EE0F59F81C585DABEDBAD227A10ECD0B8FFFA1D068A16477DA3B89CD2690D01C984A59F9DF63977000F6F1E7CF6CF440BED555FBA87A666FD05FAF1FE58BA734E0EA426052B81C904FF6E205C23C0E182F2E85C55334C89B7B83CA461C1A4DBFFA821E5020E2577BE6362DE13D09B582B434ABF37C27C2352E1E284E14A13A19FBD018BA3B3A35018A00BD23F83CF4187D24CE00895C785CF4E7D99C5DC0E3331E85C9245EEA4BB76C9CEBCA0B737831846E147AFBA51B7766&sign=FA980DE128EABE6DDA0AC8E550CEF33459F27B7D (Caused by NewConnectionError('<urllib3.connection.HTTPSConnection object at 0x7f3b8b6cc410>: Failed to establish a new connection: [Errno 101] Network is unreachable'))
### 执行结果
- **登录状态**: 登录失败
- **签到结果**: 

---
## 执行统计
- **结束时间**: 2025-09-24 10:54:48
- **运行时长**: 541.73 秒

✅ **所有账户处理完成！**
