# 天翼云盘签到记录

[![签到状态](https://github.com/211847750/189pan/actions/workflows/main.yml/badge.svg)](https://github.com/211847750/189pan/actions/workflows/main.yml) [![项目主页](https://img.shields.io/badge/GitHub-项目主页-blue?logo=github)](https://github.com/211847750/189pan)

**最后更新:** 2025-10-05 10:53:17 CST

## 快速导航

- 🔄 [查看Action运行记录](https://github.com/211847750/189pan/actions)
- 📋 [查看最新运行](https://github.com/211847750/189pan/actions/runs/18252942866)
- 🏠 [返回项目主页](https://github.com/211847750/189pan)
- ⚙️ [手动触发签到](https://github.com/211847750/189pan/actions/workflows/main.yml)

## 签到详情

# 天翼云盘自动签到抽奖程序

## 执行概览
- **启动时间**: 2025-10-05 10:53:17
- **账户数量**: 2 个

## 账户1
登录过程出错: HTTPSConnectionPool(host='open.e.189.cn', port=443): Max retries exceeded with url: /api/logbox/oauth2/autoLogin.do?appId=cloud&version=v1.1&clientType=20010&format=redirect&paras=420AD94051C80AF67D703907F8D6AF9FCD7CB447F7FAB56EBF921DD2CF9D2EB18C0497ABC39E205368F036C5F4BE96FEF887D955E97B541E271AFDE9EA07DD86270850E302E1A6FA745322B9362B3970B8E82F167D5D5278930BF9AC9EF2327DCD96090E8DB0D660CCE8F5B744343DB528C0588138ACBFA630F5BD4DA90830BB790B9FDD420ADCA489158D6D1633097BF1433845DD5AA151CA57C2C437F76803B88203540E075B28806D6D03C023D4A9D8408D7B0056A5B54C37FD52EA8737D6B3916941AA38D233661E2D48B9415A9A7430080B0D43F0BB6448CF53BA11395756187E2B40B2A25C13E8ED1A4ED0527FA83D51DD90680865F17858E5AF3C2B36564110D2CECDB7F4602B5B5FF2D522908E00F58EF63B5A85CEE1D4DF149D738225FC6CD9E8F4D113A72005FF2B6DDCF6D34AC2BFA9CC60EC6BEC81EFDE1A59FB1EA11DD8D69C80043C0CCB0A353DA001B70E86CC8D778815A949721367AD27FF256E2BC2C602AE40E265E169FB64B784B0B857CEA378D4CC53DE5F7EB28D73165EB7A9296CB7BFD8BCC1CA18D9EE6E59867D39E9D6E7844569175BDA1DA3CB0C534BD8DBDEAA714D0787D13F168E438CE4FEA9361A38C20305368248BFA01DEF97DB58649EBAC3079308ED4DBD9E2C2D6589406036AA62722657B6AF8A0F5D5054BD66CFB10F611658CD43AE6EC5D0936B21F60C7FB186A77A29D3D117A2D6B206A573498C4B929D2B582835E95F66774C18DB1C32168A95&sign=918B4115D923CB3CE2E65E72A1457DC249D25F6C (Caused by NewConnectionError('<urllib3.connection.HTTPSConnection object at 0x7f59a3560dd0>: Failed to establish a new connection: [Errno 101] Network is unreachable'))
### 执行结果
- **登录状态**: 登录失败
- **签到结果**: 

## 账户2
登录过程出错: HTTPSConnectionPool(host='open.e.189.cn', port=443): Max retries exceeded with url: /api/logbox/oauth2/autoLogin.do?appId=cloud&version=v1.1&clientType=20010&format=redirect&paras=CC7703A77CD0C173E3E30AF962CD872E3DF6C2128FA102955E1AB7CC891AA55C372369246FA3253BF7F3B695C2B4E7FB91333D3C2A5E0FAB5D06A70ECE59EB95B85329F8EFF02D9F8EA2B64871DE2817DD47A8E5706EC38CE63BD186406B9F5215FC58ABDDA366F024EE9F304C09A49096C033897A2E273E118F16A9F5B128571F58DFBDF08E838EFA4A458455DABE0061108405EE7E680B785E14448DCDC226CA96E722BBA193F9EF40F2D1EE7CF2DC57A5DABFE29E5D6AD956C6B41BA9D467A2CC1287B3885EC9F17F8D252DC7C4479F012E8D157B9EFEFB6E53EDB0AADDF881C8CB63FF52E8C0C4A213C396E9415C2E38D7B0A6716EF348E8A6E22015E5BEE7217E5AAABEA77B91474DC33B6180B6C180BBA0D56103D0E628E730E28E0B162400AD8B5FC22ED5D71B51CE28436580054073733C220F3D457C7573FD2FC6FA7E6B34C93223FDEBD579F08AAC614A5C030C8BDEBFD8EB0A479D27BD697F85E117DD78CB7CE7B2F92FC6FBFDB820DF05B6EDACC09587ACAFEBC5F4B71590E9930BCE9F3F40787DCED98B35E0B64CD54223FC8CA0AF88C4645E7532B6128D3B9340BAEE9E7E3D2404DB1AB4CEBF9425EC9249182312A20A5B01291DEB335E7B08DFFA758AF441651B5A51A8664B05F19B994F182E0D6C4774221987A68B68C6AAF9CFBFD435654D98B6BBBA27516ABFC1C78A13F792FD70FF08FE9569B301401801BDE9EFAD52192EAF85F613A6788E3DB3031E4B6BFEDED6&sign=093733568A383E29FD195C40A4A7A2CFD32AFCC7 (Caused by NewConnectionError('<urllib3.connection.HTTPSConnection object at 0x7f59a3568610>: Failed to establish a new connection: [Errno 101] Network is unreachable'))
### 执行结果
- **登录状态**: 登录失败
- **签到结果**: 

---
## 执行统计
- **结束时间**: 2025-10-05 11:02:18
- **运行时长**: 541.13 秒

✅ **所有账户处理完成！**
